# Python 用户定义的异常

> 原文:[https://www.educba.com/python-user-defined-exception/](https://www.educba.com/python-user-defined-exception/)

![Python User Defined Exception](../Images/4690412b30e68514e025667d6b7afada.png)

<noscript><img class="alignnone size-full wp-image-482607" src="../Images/4690412b30e68514e025667d6b7afada.png" alt="Python User Defined Exception" width="900" height="500" srcset="https://cdn.educba.com/academy/wp-content/uploads/2021/05/Python-User-Defined-Exception.jpg 900w, https://cdn.educba.com/academy/wp-content/uploads/2021/05/Python-User-Defined-Exception-300x167.jpg 300w, https://cdn.educba.com/academy/wp-content/uploads/2021/05/Python-User-Defined-Exception-768x427.jpg 768w" sizes="(max-width: 900px) 100vw, 900px" data-original-src="https://cdn.educba.com/academy/wp-content/uploads/2021/05/Python-User-Defined-Exception.jpg"/></noscript>

## Python 用户定义异常简介

以下文章概述了 Python 用户定义的异常。Python 用户定义的异常可以根据特定程序员的定制和要求来编写，并且在 python 的预定义异常中不存在。在进行编码和编程时，可能会发生代码在某些地方出错的情况。

在这种情况下，python 程序会抛出一个错误或异常，这有时会导致程序执行完全结束。这些情况可以通过使用用户定义的异常和 try-except 语句来处理。使用它，我们可以定义当一个特定的错误或异常发生时应该做什么，或者创建我们想要在程序中处理的新的异常。

<small>网页开发、编程语言、软件测试&其他</small>

**Python 用户定义异常的语法**

python 中常见的一些预定义异常包括 FileNotFoundError、ImportError、TypeError、IOError、IndexError 和 ZeroDivisionError。大多数异常都以错误名结尾。然而，这并不是一种强制，而是一种建议，无论何时你想要创建你自己的异常，你都应该给它起个名字，这样它就应该以 Error word 结尾，并且包含 camel-case。创建新的用户定义异常的一般方法或语法是为异常创建新的类。这个类应该直接或间接地从主异常类派生。

在 python 中创建新类的简单语法如下所示:

`Class yourUserDefinedExceptionError (Exception):`

此外，您应该指定异常的主体，比如当异常发生时您的程序应该做什么。然后，在用于异常和错误处理的 try-except 语句的帮助下，可以使用用户定义的异常。

### 如何使用异常？

我们可以使用 python 中提供的 try 和 except 等错误处理机制来使用我们定义的异常，并处理这些错误或异常。

为了获得 python 中异常的完整细节或附加信息，可以执行以下命令。

`help (Exception)`

**输出:**

执行上述命令会产生类似于下图的输出:

![Python User Defined Exception 1](../Images/be96bab5c4cdc596d81ad9fae26986cd.png)

<noscript><img class="alignnone wp-image-482118 size-full" src="../Images/be96bab5c4cdc596d81ad9fae26986cd.png" alt="Python User Defined Exception 1" width="774" height="675" srcset="https://cdn.educba.com/academy/wp-content/uploads/2021/05/Python-User-Defined-Exception-1.jpg 774w, https://cdn.educba.com/academy/wp-content/uploads/2021/05/Python-User-Defined-Exception-1-300x262.jpg 300w, https://cdn.educba.com/academy/wp-content/uploads/2021/05/Python-User-Defined-Exception-1-768x670.jpg 768w" sizes="(max-width: 774px) 100vw, 774px" data-original-src="https://cdn.educba.com/academy/wp-content/uploads/2021/05/Python-User-Defined-Exception-1.jpg"/></noscript>

![Python User Defined Exception 2](../Images/e25b067172a9981e4b70304fa0869af4.png)

<noscript><img class="alignnone wp-image-482121 size-full" src="../Images/e25b067172a9981e4b70304fa0869af4.png" alt="Python User Defined Exception 2" width="784" height="768" srcset="https://cdn.educba.com/academy/wp-content/uploads/2021/05/Python-User-Defined-Exception-2.jpg 784w, https://cdn.educba.com/academy/wp-content/uploads/2021/05/Python-User-Defined-Exception-2-300x294.jpg 300w, https://cdn.educba.com/academy/wp-content/uploads/2021/05/Python-User-Defined-Exception-2-768x752.jpg 768w" sizes="(max-width: 784px) 100vw, 784px" data-original-src="https://cdn.educba.com/academy/wp-content/uploads/2021/05/Python-User-Defined-Exception-2.jpg"/></noscript>

![Python User Defined Exception 3](../Images/1bbc345ebf1b9c7ddf0c09b3e1d52476.png)

<noscript><img class="alignnone wp-image-482122 size-full" src="../Images/1bbc345ebf1b9c7ddf0c09b3e1d52476.png" alt="Python User Defined Exception 3" width="778" height="654" srcset="https://cdn.educba.com/academy/wp-content/uploads/2021/05/Python-User-Defined-Exception-3.jpg 778w, https://cdn.educba.com/academy/wp-content/uploads/2021/05/Python-User-Defined-Exception-3-300x252.jpg 300w, https://cdn.educba.com/academy/wp-content/uploads/2021/05/Python-User-Defined-Exception-3-768x646.jpg 768w" sizes="(max-width: 778px) 100vw, 778px" data-original-src="https://cdn.educba.com/academy/wp-content/uploads/2021/05/Python-User-Defined-Exception-3.jpg"/></noscript>

### Python 用户定义异常的示例

以下是 Python 用户定义异常的示例:

#### 示例#1

让我们通过为用户定义的异常创建一个新类来创建一个小异常。out 类必须扩展基本异常类。我们的异常类名将是 MyUserDefinedError，我们将使用 ty except 来检查异常的工作情况。except 语句将有助于显示包含异常返回值的消息。

**代码:**

```
# Sample example to demonstrate the working and creation of user defined exception in python
# It is necessary that MyUserDefinedError class should be derived from the main super class of the Exception
class MyUserDefinedError(Exception):
# Initializer (Constructor) for the class
def __init__(self, value):
self.value = value
# This will help to display the message of the exception
def message(self):
return(repr(self.value))
try:
raise(MyUserDefinedError(9*8))
# returnedErrorMessage will store the value of the message or anything which will be returned by the exception
except MyUserDefinedError as returnedErrorMessage:
print ('The occurrence of the new exception is identified : ', returnedErrorMessage.value)
```

上述程序的执行给出了下面的输出，显示了从我们定义的异常类返回的计算值 9 * 8。

**输出:**

![MyUserDefinedError](../Images/77eef09a965f291810e0ed159f8fbea9.png)

<noscript><img class="alignnone wp-image-482123 size-full" src="../Images/77eef09a965f291810e0ed159f8fbea9.png" alt="MyUserDefinedError" width="773" height="65" srcset="https://cdn.educba.com/academy/wp-content/uploads/2021/05/Python-User-Defined-Exception-4.jpg 773w, https://cdn.educba.com/academy/wp-content/uploads/2021/05/Python-User-Defined-Exception-4-300x25.jpg 300w, https://cdn.educba.com/academy/wp-content/uploads/2021/05/Python-User-Defined-Exception-4-768x65.jpg 768w" sizes="(max-width: 773px) 100vw, 773px" data-original-src="https://cdn.educba.com/academy/wp-content/uploads/2021/05/Python-User-Defined-Exception-4.jpg"/></noscript>

#### 实施例 2

让我们再考虑一个用户定义异常的例子。在这个例子中，我们将尝试从 Exception 的超类中导出错误。这种类型的超类异常主要在我们有一个应该处理许多不同类型错误的模块时使用。我们将尝试通过使用该模块来定义异常的基类来实现这一点。然后，将创建不同的子类，为需要处理的不同的可能错误定义每个异常类。

**代码:**

```
# Class which is derived from the main base class of Exception is DerivedClassError class
class DerivedClassError(Exception):
# Even though DerivedClassError is derived from the main base class of exceptions,
# it will be used and considered as the base class for our user defined exception class
pass
class TransDerivedClassError(DerivedClassError):
# This transition will occur when the transition will try to
# perform the state which is actually not permitted to it
def __init__(self, previous, next, message):
self.previous = previous
self.next = next
# message will store the value generated from the error
self.message = message
try:
raise(TransDerivedClassError(4,6*4,"Not Permitted"))
# DerivedClassError will store the value of the user defined exception
except TransDerivedClassError as DerivedClassError:
print('There is an occurrence of exception: ',DerivedClassError.message)
```

上述程序的执行给出了下面的输出，显示了从我们定义的异常类返回的消息“不允许”。

**输出:**

![try to derive the error from the super class](../Images/35a1fc9c585f7f2276773a4fee30ebd8.png)

<noscript><img class="alignnone wp-image-482125 size-full" src="../Images/35a1fc9c585f7f2276773a4fee30ebd8.png" alt="try to derive the error from the super class" width="733" height="58" srcset="https://cdn.educba.com/academy/wp-content/uploads/2021/05/Python-User-Defined-Exception-5.jpg 733w, https://cdn.educba.com/academy/wp-content/uploads/2021/05/Python-User-Defined-Exception-5-300x24.jpg 300w" sizes="(max-width: 733px) 100vw, 733px" data-original-src="https://cdn.educba.com/academy/wp-content/uploads/2021/05/Python-User-Defined-Exception-5.jpg"/></noscript>

#### 实施例 3

在创建新的用户定义异常时，我们甚至可以将标准的预定义异常视为基类。让我们考虑这种类型的一个例子。当发生的错误在任何可用的异常类别中都不被考虑时，将引发 RuntimeError。RuntimeError 是 python 中的内置异常。因此，我们可以将这个类视为我们的用户定义类的基类，而不是主异常类。下面的程序说明了相同的用法。

**代码:**

```
# SampleError is derived from the RuntimeError instead of main base class of Exception
class SampleError(RuntimeError):
def __init__(self, arg):
self.args = arg
try:
raise SampleError("Exception")
except SampleError as message:
print (message.args)
```

上述程序的执行给出了以下输出，其工作方式与我们必须扩展主异常类而不是 RuntimeError 类作为基类的情况类似。

**输出:**

![standard predefined exceptions](../Images/065ea0c768eae7709d37c4926b36c1d0.png)

<noscript><img class="alignnone wp-image-482128 size-full" src="../Images/065ea0c768eae7709d37c4926b36c1d0.png" alt="standard predefined exceptions" width="648" height="44" srcset="https://cdn.educba.com/academy/wp-content/uploads/2021/05/Python-User-Defined-Exception-6.jpg 648w, https://cdn.educba.com/academy/wp-content/uploads/2021/05/Python-User-Defined-Exception-6-300x20.jpg 300w" sizes="(max-width: 648px) 100vw, 648px" data-original-src="https://cdn.educba.com/academy/wp-content/uploads/2021/05/Python-User-Defined-Exception-6.jpg"/></noscript>

### 结论

在 python 的程序中，我们可以根据需要定义异常。有许多方法可以创建这些异常。在 python 中，可以通过简单的异常处理机制 try 和 except 来处理它们，就像处理其他预定义的异常一样。

### 推荐文章

这是 Python 用户定义异常的指南。这里我们讨论一下入门，如何使用异常？和示例。您也可以看看以下文章，了解更多信息–

1.  [Python 中的 Shell 排序](https://www.educba.com/shell-sort-in-python/)
2.  [Python 中的插入排序](https://www.educba.com/insertion-sort-in-python/)
3.  [蟒蛇皮烧瓶](https://www.educba.com/flask-in-python/)
4.  [Python 列表扩展](https://www.educba.com/python-list-extend/)

<footer class="entry-footer">

<aside class="sidebar sidebar-primary widget-area" role="complementary" aria-label="Primary Sidebar">Primary Sidebar</aside>

</footer>