# C#中异常的类型

> 原文:[https://www.educba.com/types-of-exception-in-c-sharp/](https://www.educba.com/types-of-exception-in-c-sharp/)

![Types of Exception in C#](../Images/510558d7761ad3837141726c76f463f4.png)

<noscript><img class="alignnone size-full wp-image-375490" src="../Images/510558d7761ad3837141726c76f463f4.png" alt="Types of Exception in C#" width="900" height="500" srcset="https://cdn.educba.com/academy/wp-content/uploads/2020/06/Types-of-Exception-in-C.jpg 900w, https://cdn.educba.com/academy/wp-content/uploads/2020/06/Types-of-Exception-in-C-300x167.jpg 300w, https://cdn.educba.com/academy/wp-content/uploads/2020/06/Types-of-Exception-in-C-768x427.jpg 768w" sizes="(max-width: 900px) 100vw, 900px" data-original-src="https://cdn.educba.com/academy/wp-content/uploads/2020/06/Types-of-Exception-in-C.jpg"/></noscript>

## C#中异常类型介绍

在程序执行期间出现的问题是异常，这些异常是对程序运行期间异常情况的响应，例如每当我们试图除以零时出现的异常，控制通过异常从程序的一部分转移到程序的另一部分，异常的处理由 C#中的四个关键字管理，它们是 try、catch、finally 和 throw 块。

### C#中的异常类型及示例

C#中有几种类型的异常。它们是:

<small>网页开发、编程语言、软件测试&其他</small>

#### 1.系统。out of memory 异常

由于可用内存不足而生成的错误由该异常处理。考虑下面的示例程序来演示系统。OutOfMemoryException。

**举例:**

```
//a class called check is defined
public class check
{
//main method is called
public static void Main()
{
// a string variable is created and tried to store 2.1 billion characters and this causes an out of memory exception
string val = new string('r', int.MaxValue);
}
}
```

**输出:**

![Types of Exception in C#-1.1](../Images/eb31b6bd822eb1e92af0cf9003ceb4be.png)

<noscript><img class="alignnone size-full wp-image-372369" src="../Images/eb31b6bd822eb1e92af0cf9003ceb4be.png" alt="Types of Exception in C#-1.1" width="683" height="266" srcset="https://cdn.educba.com/academy/wp-content/uploads/2020/05/Types-of-Exception-in-C-1.1.png 683w, https://cdn.educba.com/academy/wp-content/uploads/2020/05/Types-of-Exception-in-C-1.1-300x117.png 300w" sizes="(max-width: 683px) 100vw, 683px" data-original-src="https://cdn.educba.com/academy/wp-content/uploads/2020/05/Types-of-Exception-in-C-1.1.png"/></noscript>

**输出:**

在上面的程序中，定义了一个名为 check 的类。然后调用 main 方法。创建了一个字符串变量，并试图存储 21 亿个字符，这导致了内存不足异常。

#### 2.系统。NullReferenceException

通过引用空对象生成的错误由该异常处理。考虑下面的示例程序来演示系统。NullReferenceException

**举例**:

```
using System;
//a class called check is defined
class check
{
//main method is called
static void Main()
{
//a string variable is defined, and it is referencing to null
string value = null;
//the length of the value referencing to null is checked if it is equal to zero causing an exception
if (value.Length == 0)
{
Console.WriteLine(value);
}
}
}
```

**输出:**

![Types of Exception in C#-1.2](../Images/b0f85a57c3ec60cd661807127419996f.png)

<noscript><img class="alignnone size-full wp-image-372370" src="../Images/b0f85a57c3ec60cd661807127419996f.png" alt="Types of Exception in C#-1.2" width="705" height="129" srcset="https://cdn.educba.com/academy/wp-content/uploads/2020/05/Types-of-Exception-in-C-1.2.png 705w, https://cdn.educba.com/academy/wp-content/uploads/2020/05/Types-of-Exception-in-C-1.2-300x55.png 300w" sizes="(max-width: 705px) 100vw, 705px" data-original-src="https://cdn.educba.com/academy/wp-content/uploads/2020/05/Types-of-Exception-in-C-1.2.png"/></noscript>

在上面的程序中，定义了一个名为 check 的类。然后调用 main 方法。然后定义一个字符串变量，它引用 null。则检查引用 null 的值的长度，如果它等于零，则导致异常。

#### 3.系统。InvalidCastException

类型转换期间生成的错误由该异常处理。考虑下面的示例程序来演示系统。InvalidCastException。

**举例:**

```
using System.IO;
using System.Text;
//a class called check is defined
class check
{
//main method is called
static void Main()
{
// an instance of the string builder class is created which is then assigned to a new object through implicit casting and then casting is tried explicitly to convert the instance of stringbuilder class to streamreader class
StringBuilder ref1 = new StringBuilder();
object ref2 = ref1;
StreamReader ref3 = (StreamReader)ref2;
}
}
```

**输出:**

![Types of Exception in C#-1.3](../Images/2c967108d375568de9e3801ee7667c3a.png)

<noscript><img class="alignnone size-full wp-image-372371" src="../Images/2c967108d375568de9e3801ee7667c3a.png" alt="Types of Exception in C#-1.3" width="778" height="117" srcset="https://cdn.educba.com/academy/wp-content/uploads/2020/05/Types-of-Exception-in-C-1.3.png 778w, https://cdn.educba.com/academy/wp-content/uploads/2020/05/Types-of-Exception-in-C-1.3-300x45.png 300w, https://cdn.educba.com/academy/wp-content/uploads/2020/05/Types-of-Exception-in-C-1.3-768x115.png 768w" sizes="(max-width: 778px) 100vw, 778px" data-original-src="https://cdn.educba.com/academy/wp-content/uploads/2020/05/Types-of-Exception-in-C-1.3.png"/></noscript>

在上面的程序中，定义了一个名为 check 的类。然后调用 main 方法。然后创建 string builder 类的实例，然后通过隐式强制转换将该实例分配给新对象，然后显式尝试强制转换，将 stringbuilder 类的实例转换为 streamreader 类，这会导致异常。

#### 4.系统。ArrayTypeMismatchException

当类型与数组类型不匹配时生成的错误由此异常处理。考虑下面的示例程序来演示系统。ArrayTypeMismatchException。

**举例:**

```
//a class called check is defined
class check
{
//main method is called
static void Main()
{
// a string is defined and assigned the values which is then assigned to object class array and then an integer is tried to put in the same array which causes an exception
string[] arr1 = { "Welcome", "to", "CSharp" };
object[] arr2 = arr1;
arr2[0] = 8;
}
}
```

**输出:**

![Types of Exception in C#-1.4](../Images/0917ea6345581c5b2c7aa99a0f3e044e.png)

<noscript><img class="alignnone size-full wp-image-372372" src="../Images/0917ea6345581c5b2c7aa99a0f3e044e.png" alt="Types of Exception in C#-1.4" width="753" height="190" srcset="https://cdn.educba.com/academy/wp-content/uploads/2020/05/Types-of-Exception-in-C-1.4.png 753w, https://cdn.educba.com/academy/wp-content/uploads/2020/05/Types-of-Exception-in-C-1.4-300x76.png 300w" sizes="(max-width: 753px) 100vw, 753px" data-original-src="https://cdn.educba.com/academy/wp-content/uploads/2020/05/Types-of-Exception-in-C-1.4.png"/></noscript>

在上面的程序中，定义了一个名为 check 的类。然后定义主方法。然后，定义一个字符串并为其赋值，然后将其赋值给 object 类 array，然后尝试将一个整数放入同一个数组中，这将导致异常。

#### 5.系统。IndexOutOfRangeException

当方法引用超出范围的数组时生成的错误由此异常处理。考虑下面的示例程序来演示系统。IndexOutOfRangeException。

**举例:**

```
//a class called check is defined
class check
{
//main method is called
static void Main()
{
// an array is defined to store 100 integers but then an integer is tried to be stores at a position outside of the size of the array which causes an exception
int[] arr = new int[10];
arr[0] = 10;
arr[10] = 20;
arr[20] = 30;
}
}
```

**输出:**

![Types of Exception in C#-1.5](../Images/52f8038a8e615214eabd59d168e0403e.png)

<noscript><img class="alignnone size-full wp-image-372373" src="../Images/52f8038a8e615214eabd59d168e0403e.png" alt="Types of Exception in C#-1.5" width="653" height="130" srcset="https://cdn.educba.com/academy/wp-content/uploads/2020/05/Types-of-Exception-in-C-1.5.png 653w, https://cdn.educba.com/academy/wp-content/uploads/2020/05/Types-of-Exception-in-C-1.5-300x60.png 300w" sizes="(max-width: 653px) 100vw, 653px" data-original-src="https://cdn.educba.com/academy/wp-content/uploads/2020/05/Types-of-Exception-in-C-1.5.png"/></noscript>

在上面的程序中，定义了一个名为 check 的类。然后调用 main 方法。然后一个数组被定义为存储 100 个整数，但是随后一个整数试图被存储在数组大小之外的位置，这导致了一个异常。

#### 6.系统。DivideByZeroException

被除数被零除时产生的错误由此异常处理。考虑下面的示例程序来演示系统。DivideByZeroException。

**举例:**

```
using System;
//a class called check is defined
class check
{
//main method is called
static void Main()
{
//an integer variable res is defined which is tried to divide by zero which causes an exception
int res = 10 / int.Parse("0");
Console.WriteLine(res);
}
}
```

**输出:**

![Output-1.6](../Images/caec805414a984de2aad002d811998e1.png)

<noscript><img class="alignnone wp-image-372375 size-full" src="../Images/caec805414a984de2aad002d811998e1.png" alt="Output-1.6" width="634" height="134" srcset="https://cdn.educba.com/academy/wp-content/uploads/2020/05/Types-of-Exception-in-C-1.6.png 634w, https://cdn.educba.com/academy/wp-content/uploads/2020/05/Types-of-Exception-in-C-1.6-300x63.png 300w" sizes="(max-width: 634px) 100vw, 634px" data-original-src="https://cdn.educba.com/academy/wp-content/uploads/2020/05/Types-of-Exception-in-C-1.6.png"/></noscript>

在上面的程序中，定义了一个名为 check 的类。然后调用 main 方法。然后定义一个整数变量 res，试图除以零，这将导致异常。

#### 7.系统。堆栈溢出异常

由堆栈溢出生成的错误由该异常处理。考虑下面的示例程序来演示系统。StackOverflowException。

**举例:**

```
using System;
//a class called check is defined
public class check
{
// a method called recurse is defined which takes a value as parameter and increases its value by one
static void Recurse(int val)
{
// since we have written a recursive loop and 0 is passed as a parameter, it ends in an infinite loop causing exception
Console.WriteLine(val);
Recurse(++val);
}
//main method is called
public static void Main()
{
//The recurse method is called to start the infinite recursion
Recurse(0);
}
}
Output:
```

![Output-1.7](../Images/90e41f25dcb701ff122ce04b95d88f1a.png)

<noscript><img class="alignnone wp-image-372377 size-full" src="../Images/90e41f25dcb701ff122ce04b95d88f1a.png" alt="Output-1.7" width="990" height="174" srcset="https://cdn.educba.com/academy/wp-content/uploads/2020/05/Types-of-Exception-in-C-1.7.png 990w, https://cdn.educba.com/academy/wp-content/uploads/2020/05/Types-of-Exception-in-C-1.7-300x53.png 300w, https://cdn.educba.com/academy/wp-content/uploads/2020/05/Types-of-Exception-in-C-1.7-768x135.png 768w" sizes="(max-width: 990px) 100vw, 990px" data-original-src="https://cdn.educba.com/academy/wp-content/uploads/2020/05/Types-of-Exception-in-C-1.7.png"/></noscript>

在上面的程序中，定义了一个名为 check 的类。然后定义了一个名为 recurse 的方法，该方法将一个值作为参数，并将其值加 1。然后调用 main 方法，在该方法中，通过将零作为参数传递来开始递归的无限循环。然后，由于我们已经编写了一个递归循环，0 作为参数传递，它在一个无限循环中结束，导致异常。

#### 8.系统。IO 异常

输入产生的错误，输出由这个异常处理。考虑下面的示例程序来演示系统。IO。IOException。

**举例:**

```
using System;
using System.IO;
//a class called check is defined
class check
{
//main methos is called
static void Main()
{
try
{
//a file is tried to open which do not exist and causes an exception
File.Open("D:\\ex.txt", FileMode.Open);
}
catch (IOException)
{
Console.WriteLine("Inputoutput Exception is handled");
}
}
}
```

**输出:**

![Output-1.8](../Images/e9cedf8cbf2e2169803488380edc8190.png)

<noscript><img class="alignnone wp-image-372378 size-full" src="../Images/e9cedf8cbf2e2169803488380edc8190.png" alt="Output-1.8" width="296" height="30" data-original-src="https://cdn.educba.com/academy/wp-content/uploads/2020/05/Types-of-Exception-in-C-1.8.png"/></noscript>

在上面的程序中，定义了一个名为 check 的类。然后调用 main 方法。然后试图打开一个不存在的文件并导致异常。

### 推荐文章

这是 C#中异常类型的指南。在这里，我们还讨论了 c#中异常的介绍和几种类型，以及不同的例子和代码实现。

1.  [C#动作委托](https://www.educba.com/c-sharp-action-delegate/)
2.  [c#中的自定义异常](https://www.educba.com/custom-exception-in-c-sharp/)
3.  [C # out of memory 异常](https://www.educba.com/c-sharp-outofmemoryexception/)
4.  [C#堆栈溢出异常](https://www.educba.com/c-sharp-stackoverflowexception/)

<footer class="entry-footer">

<aside class="sidebar sidebar-primary widget-area" role="complementary" aria-label="Primary Sidebar">Primary Sidebar</aside>

</footer>