# JUnit 断言异常

> 原文:[https://www.educba.com/junit-assert-exception/](https://www.educba.com/junit-assert-exception/)

![JUnit assert exception](../Images/71c1894349a45c849345b20324e6f083.png)

<noscript><img class="alignnone size-full wp-image-525357" src="../Images/71c1894349a45c849345b20324e6f083.png" alt="JUnit assert exception" width="900" height="500" srcset="https://cdn.educba.com/academy/wp-content/uploads/2022/05/JUnit-assert-exception.jpg 900w, https://cdn.educba.com/academy/wp-content/uploads/2022/05/JUnit-assert-exception-300x167.jpg 300w, https://cdn.educba.com/academy/wp-content/uploads/2022/05/JUnit-assert-exception-768x427.jpg 768w" sizes="(max-width: 900px) 100vw, 900px" data-original-src="https://cdn.educba.com/academy/wp-content/uploads/2022/05/JUnit-assert-exception.jpg"/></noscript>

## JUnit 断言异常的定义

JUnit 是一个开源工具，它为开发人员提供了不同类型的异常，其中断言是 JUnit 中可用的异常之一。基本上 assert 用于验证功能。通常，这需要一个普通的特例和一个可执行的实际连接点，在这里我们可以通过 lambda 连接来完成代码。换句话说，我们可以说断言异常是用来在条件不匹配时抛出异常的，断言我们可以根据自己的要求实现的异常。

### 什么是 JUnit 断言异常？

JUnit 提供了遵循代码豁免处理的选择。您可以测试代码是否抛出了理想的豁免。正常边界与@Test 注释一起使用。允许我们在现实生活中看到@Test(预期)。

<small>网页开发、编程语言、软件测试&其他</small>

此外，重要的是要注意，当被封装的代码抛出 NumberFormatException 类型的特例或其任何确定的排序时，这种断言就实现了。

这意味着假设我们将 Exception 作为普通的特例类型传递，任何被丢弃的豁免都将导致声明生效，因为 Exception 是所有特例的超类型。

为了为一个特殊的情况编写和运行实验，我们希望框架中有 JUnit 容器记录，或者我们真的希望在我们的框架中设置 JUnit 气候。为了测试特殊情况，我们应该遵循相应的进展:

*   创建一个班级进行测试
*   为测试特殊情况制作一个实验班
*   创建一个测试运行器类来执行实验

### JUnit 断言异常测试

该股让办公室跟踪特殊情况，并进一步检查守则是否放弃预期的豁免。JUnit4 给出了一个简单而一致的方法来进行豁免测试，你可以利用它

@test comment 的任意边界(预期),在测试特殊情况时，您真的希望保证您在@ test explanation 的任意边界中给出的豁免类是类似的。这是因为您期望从您正在进行单元测试的策略中得到豁免，无论如何，我们的 JUnit 测试将会失败。

示例@Test(预期=exception.class)

通过利用“预期的”边界，您可以确定我们的测试可能抛出的特例名称。在上面的模型中，你利用了一个“异常”,这个异常将被测试抛出，如果设计者利用了一个不允许的争用。现在让我们看看下面的例子，以便更好地理解。

首先，我们需要创建一个类 sampletest，并编写如下代码。

```
package com.demo;
public class sampletest {
private String msg;
//Constructor
//@param message to be printed
public sampletest(String msg){
this.msg = msg;
}
// prints the message
public void printmsg(){
System.out.println("Specified msg");
int x = 0;
int y = 1/x;
}
// add to the message
public String addmsg(){
msg = "string " + msg;
System.out.println(msg);
return msg;
}
}
```

**解释**

在上面的程序中，我们试图实现一个被零除的异常。现在我们需要创建一个测试类，并编写如下代码。

```
import org.JUnit.Test;
import org.JUnit.Ignore;
import static org.JUnit.Assert.assertEquals;
public class demotest {
String msg = "Harry";
sampletest sampletest = new sampletest(msg);
@Test(expected = ArithmeticException.class)
public void PrintMessage() {
System.out.println("printMessage");
sampletest.PrintMessage();
}
@Test
public void testMessage() {
System.out.println("addmsg");
msg = "Result of" + "Harry";
System.out.println("msg ");
assertEquals(msg,sampletest.printmsg());
}
}
```

现在我们需要创建 runner 类来执行程序，如下所示。

```
import org.JUnit.runner.JUnitCore;
import org.JUnit.runner.Result;
import org.JUnit.runner.notification.Failure;
public class TestRunner {
public static void main(String[] args) {
r r = JUnitCore.runClasses(demotest.class);
for (Failure failure : r.getFailures()) {
System.out.println(failure.toString());
}
System.out.println(r.wasSuccessful());
}
}
```

**解释**

在上面的代码中，我们实现了测试运行器来查看结果。上面实现的最终结果我们用下面的截图来说明。

![28](../Images/ce04a5830d5228c5fe774487e9d83ec6.png)

<noscript><img class="alignnone size-full wp-image-525147" src="../Images/ce04a5830d5228c5fe774487e9d83ec6.png" alt="28" width="335" height="146" srcset="https://cdn.educba.com/academy/wp-content/uploads/2022/02/28.png 335w, https://cdn.educba.com/academy/wp-content/uploads/2022/02/28-300x131.png 300w" sizes="(max-width: 335px) 100vw, 335px" data-original-src="https://cdn.educba.com/academy/wp-content/uploads/2022/02/28.png"/></noscript>

### JUnit 断言异常消息

现在让我们看看 assert 中的一条消息，如下所示。在测试代码时，你经常需要测试特定的豁免和消息是否被抛出。JUnit 实现这一点的技术是 Assertions.assertThrows。因此，为了测试是否抛出了 NullPointerException，我们将利用以下方法:

asserts . assert throws(nullpointerexception . class，()--> { codethethrowsnpe；})文档中不令人满意的一点是测试豁免消息的方式。

现在让我们来看一个例子，以便更好地理解。

```
exceptionThatWasThrown: Throwable =
assertThrows(NullPointerException::class.java) {
codeThatThrows
}
assertThat(exceptionThatWasThrown.message, equalTo("Msg Exception thrown"))
```

### JUnit 断言异常示例

现在，为了更好地理解，让我们看看下面的不同例子。

```
package com.demo;
public class Cal{
public static int max(int array[]){
int m=0;
for(int i=1;i<array.length;i++){
if(m<array[i])
m=array[i];
}
return m;
}
}
```

**解释**

这里我们创建 Cal 类并编写上面的代码，这里我们试着找出最大数数组。上面的代码显示了查找最大数的逻辑。

这里，我们使用的是 JUnit 4，所以没有令人信服的理由去获取 TestCase 类。原理测试代码是用 maxnumber()方法编写的。在任何情况下，我们同样可以在每次测试时发挥出一些承诺，代码如下所示。

```
package com.demo;
import static org.JUnit.Assert.*;
import com.javatpoint.logic.*;
import org.JUnit.Test;
public class TestCase{
@Test
public void testFindMax(){
assertEquals(5,Cal.max(new int[]{2,4,5,1}));
assertEquals(-2,Cal.max(new int[]{-13,-2,-4,-6,-8}));
}
}
```

**解释**

在上面的代码中，我们可以看到我们试图传递负值，而 max 函数返回 0，所以这是不正确的逻辑。上面实现的最终结果我们用下面的截图来说明。

![29](../Images/ad7b70d6815a87ab00d2bf82da3fa06a.png)

<noscript><img class="alignnone size-full wp-image-525148" src="../Images/ad7b70d6815a87ab00d2bf82da3fa06a.png" alt="29" width="249" height="45" data-original-src="https://cdn.educba.com/academy/wp-content/uploads/2022/02/29.png"/></noscript>

现在在程序上面写正确的逻辑如下。

```
package com.demo;
public class Cal{
public static int max(int array[]){
int m=array[0];
for(int i=1;i<array.length;i++){
if(m<array[i])
m=array[i];
}
return m;
}
}
```

**解释**

在上面的程序中，我们只是在声明中做了修改，我们写 m = array [0]而不是 m = 0，如上面的代码所示。保存程序并运行。

### 结论

我们希望通过这篇文章，您能够了解更多关于 JUnit assert 异常的知识。从上面的文章中，我们已经理解了 JUnit 断言异常的基本思想，我们还看到了 JUnit 断言异常的表示和示例。从本文中，我们了解了如何以及何时使用 JUnit 断言异常。

### 推荐文章

这是一个 JUnit 断言异常的指南。这里我们讨论定义，什么是 JUnit 断言异常，消息，代码实现的例子。你也可以看看下面的文章来了解更多-

1.  [JUnit 参数化测试](https://www.educba.com/junit-parameterized-test/)
2.  朱尼特木星
3.  [JUnit 5 Maven 依赖](https://www.educba.com/junit-5-maven-dependency/)
4.  [JUnit 测试套件](https://www.educba.com/junit-test-suite/)

<footer class="entry-footer">

<aside class="sidebar sidebar-primary widget-area" role="complementary" aria-label="Primary Sidebar">Primary Sidebar</aside>

</footer>